I'm sorry, but an uncaught exception occurred.

While running game code:
  File "game/script2.rpy", line 53, in script
    s "Play along."
Exception: Sayer 's' is not defined.

-- Full Traceback ------------------------------------------------------------

Full traceback:
  File "game/script2.rpy", line 53, in script
    s "Play along."
  File "/Users/jayokuo/Desktop/renpy-8.3.3-sdk/renpy/ast.py", line 2573, in execute
    Say.execute(self)
  File "/Users/jayokuo/Desktop/renpy-8.3.3-sdk/renpy/ast.py", line 575, in execute
    who = eval_who(self.who, self.who_fast)
  File "/Users/jayokuo/Desktop/renpy-8.3.3-sdk/renpy/ast.py", line 464, in eval_who
    raise Exception("Sayer '%s' is not defined." % who)
Exception: Sayer 's' is not defined.

macOS-14.5-arm64-arm-64bit arm64
Ren'Py 8.3.3.24111502
3 More Days 1.1
Tue Apr 15 20:55:47 2025
